import * as React from 'react'
import userEvent from '@testing-library/user-event'
import {render, screen} from '@testing-library/react'
import {ErrorBoundary, useErrorHandler} from '..'
import type {FallbackProps} from '..'

function ErrorFallback({error, resetErrorBoundary}: FallbackProps) {
  return (
    <div role="alert">
      <p>Something went wrong:</p>
      <pre>{error.message}</pre>
      <button onClick={resetErrorBoundary}>Try again</button>
    </div>
  )
}

const firstLine = (str: string) => str.split('\n')[0]

test('handleError forwards along async errors', async () => {
  function AsyncBomb() {
    const [explode, setExplode] = React.useState(false)
    const handleError = useErrorHandler()
    React.useEffect(() => {
      if (explode) {
        setTimeout(() => {
          handleError(new Error('ðŸ’¥ CABOOM ðŸ’¥'))
        })
      }
    })
    return <button onClick={() => setExplode(true)}>bomb</button>
  }
  render(
    <ErrorBoundary FallbackComponent={ErrorFallback}>
      <AsyncBomb />
    </ErrorBoundary>,
  )

  userEvent.click(screen.getByRole('button', {name: /bomb/i}))

  await screen.findByRole('alert')

  const consoleError = console.error as jest.Mock<void, unknown[]>
  const [[actualError], [componentStack]] = consoleError.mock.calls
  const firstLineOfError = firstLine(actualError as string)
  expect(firstLineOfError).toMatchInlineSnapshot(
    `"Error: Uncaught [Error: ðŸ’¥ CABOOM ðŸ’¥]"`,
  )
  expect(componentStack).toMatchInlineSnapshot(`
    "The above error occurred in one of your React components:

        at <PROJECT_ROOT>/src/__tests__/hook.tsx:21:41
        at ErrorBoundary (<PROJECT_ROOT>/src/index.tsx:66:3)

    React will try to recreate this component tree from scratch using the error boundary you provided, ErrorBoundary."
  `)
  expect(consoleError).toHaveBeenCalledTimes(2)
  consoleError.mockClear()

  // can recover
  userEvent.click(screen.getByRole('button', {name: /try again/i}))
  expect(console.error).not.toHaveBeenCalled()
})

test('can pass an error to useErrorHandler', async () => {
  function AsyncBomb() {
    const [error, setError] = React.useState<Error | null>(null)
    const [explode, setExplode] = React.useState(false)
    useErrorHandler(error)
    React.useEffect(() => {
      if (explode) {
        setTimeout(() => {
          setError(new Error('ðŸ’¥ CABOOM ðŸ’¥'))
        })
      }
    })
    return <button onClick={() => setExplode(true)}>bomb</button>
  }
  render(
    <ErrorBoundary FallbackComponent={ErrorFallback}>
      <AsyncBomb />
    </ErrorBoundary>,
  )

  userEvent.click(screen.getByRole('button', {name: /bomb/i}))

  await screen.findByRole('alert')

  const consoleError = console.error as jest.Mock<void, unknown[]>
  const [[actualError], [componentStack]] = consoleError.mock.calls
  const firstLineOfError = firstLine(actualError as string)
  expect(firstLineOfError).toMatchInlineSnapshot(
    `"Error: Uncaught [Error: ðŸ’¥ CABOOM ðŸ’¥]"`,
  )
  expect(componentStack).toMatchInlineSnapshot(`
    "The above error occurred in one of your React components:

        at <PROJECT_ROOT>/src/__tests__/hook.tsx:66:37
        at ErrorBoundary (<PROJECT_ROOT>/src/index.tsx:66:3)

    React will try to recreate this component tree from scratch using the error boundary you provided, ErrorBoundary."
  `)
  expect(consoleError).toHaveBeenCalledTimes(2)
  consoleError.mockClear()

  // can recover
  userEvent.click(screen.getByRole('button', {name: /try again/i}))
  expect(console.error).not.toHaveBeenCalled()
})
